<?xml version="1.0"?>
<robot name="limo">
    <!-- base link -->
    <link name="base_link">
    </link>

    <!-- chassis link -->
    <joint name="chassis_joint" type="fixed">
        <origin xyz="0.0 0.0 0.095" rpy="0.0 0.0 1.57"/>
        <parent link="base_link"/>
        <child link="chassis"/>
    </joint>

    <link name="chassis">
        <inertial>
            <origin xyz="0.0 0.0 0.0" rpy="0.0 0.0 0.0"/>
            <mass value="3.0"/>
            <inertia ixx="0.0" ixy="0.0" ixz="0.0" iyy="0.0" iyz="0.0" izz="0.0"/>
        </inertial>
        <visual name="">
            <origin xyz="0.0 0.0 0.0" rpy="0.0 0.0 0.0"/>
            <geometry>
                <box size="0.13 0.20 0.1"/>
            </geometry>
            <material name="">
                <color rgba="1.0 1.0 1.0 1.0"/>
                <texture filename=""/>
            </material>
        </visual>
        <collision>
            <origin xyz="0.0 0.0 0.0" rpy="0.0 0.0 0.0"/>
            <geometry>
                <box size="0.13 0.20 0.1"/>
            </geometry>
        </collision>
    </link>

    <!-- font left wheel -->
    <joint name="font_left_wheel_joint" type="revolute">
        <origin xyz="0.10 0.07 0.045" rpy="0.0 0.0 0.0"/>
        <parent link="base_link"/>
        <child link="font_left_wheel_joint_link"/>
        <axis xyz="0.0 0.0 1.0"/>
        <limit lower="-1.57" upper="1.57" effort="0.0" velocity="0.0"/>
    </joint>

    <link name="font_left_wheel_joint_link">
    </link>

    <joint name="font_left_wheel" type="continuous">
        <origin xyz="0.0 0.0 0.0" rpy="-1.57 0.0 0.0"/>
        <parent link="font_left_wheel_joint_link"/>
        <child link="font_left_wheel_link"/>
        <axis xyz="0.0 0.0 1.0"/>
        <limit lower="0.0" upper="0.0" effort="0.0" velocity="0.0"/>
    </joint>

    <link name="font_left_wheel_link">
        <inertial>
            <origin xyz="0.0 0.0 0.0" rpy="0.0 0.0 0.0"/>
            <mass value="0.0"/>
            <inertia ixx="0.0" ixy="0.0" ixz="0.0" iyy="0.0" iyz="0.0" izz="0.0"/>
        </inertial>
        <visual name="">
            <origin xyz="0.0 0.0 0.0" rpy="0.0 0.0 0.0"/>
            <geometry>
                <cylinder radius="0.045" length="0.01"/>
            </geometry>
            <material name="">
                <color rgba="0.0 0.0 0.0 1.0"/>
                <texture filename=""/>
            </material>
        </visual>
        <collision>
            <origin xyz="0.0 0.0 0.0" rpy="0.0 0.0 0.0"/>
            <geometry>
                 <cylinder radius="0.045" length="0.01"/>
            </geometry>
        </collision>
    </link>

    <!-- right front wheel -->
    <joint name="font_right_wheel_joint" type="revolute">
        <origin xyz="0.10 -0.07 0.045" rpy="0.0 0.0 0.0"/>
        <parent link="base_link"/>
        <child link="font_right_wheel_joint_link"/>
        <axis xyz="0.0 0.0 1.0"/>
        <limit lower="-1.57" upper="1.57" effort="0.0" velocity="0.0"/>
    </joint>

    <link name="font_right_wheel_joint_link">
    </link>

    <joint name="font_right_wheel" type="continuous">
        <origin xyz="0.0 0.0 0.0" rpy="-1.57 0.0 0.0"/>
        <parent link="font_right_wheel_joint_link"/>
        <child link="font_right_wheel_link"/>
        <axis xyz="0.0 0.0 1.0"/>
        <limit lower="0.0" upper="0.0" effort="0.0" velocity="0.0"/>
    </joint>

    <link name="font_right_wheel_link">
        <inertial>
            <origin xyz="0.0 0.0 0.0" rpy="0.0 0.0 0.0"/>
            <mass value="0.0"/>
            <inertia ixx="0.0" ixy="0.0" ixz="0.0" iyy="0.0" iyz="0.0" izz="0.0"/>
        </inertial>
        <visual name="">
            <origin xyz="0.0 0.0 0.0" rpy="0.0 0.0 0.0"/>
            <geometry>
                <cylinder radius="0.045" length="0.01"/>
            </geometry>
            <material name="">
                <color rgba="0.0 0.0 0.0 1.0"/>
                <texture filename=""/>
            </material>
        </visual>
        <collision>
            <origin xyz="0.0 0.0 0.0" rpy="0.0 0.0 0.0"/>
            <geometry>
                 <cylinder radius="0.045" length="0.01"/>
            </geometry>
        </collision>
    </link>

    <!-- back left wheel -->
    <joint name="back_left_wheel" type="continuous">
        <origin xyz="-0.10 0.07 0.045" rpy="-1.57 0.0 0.0"/>
        <parent link="base_link"/>
        <child link="back_left_wheel_link"/>
        <axis xyz="0.0 0.0 1.0"/>
        <limit lower="0.0" upper="0.0" effort="0.0" velocity="0.0"/>
    </joint>

    <link name="back_left_wheel_link">
        <inertial>
            <origin xyz="0.0 0.0 0.0" rpy="0.0 0.0 0.0"/>
            <mass value="0.0"/>
            <inertia ixx="0.0" ixy="0.0" ixz="0.0" iyy="0.0" iyz="0.0" izz="0.0"/>
        </inertial>
        <visual name="">
            <!-- <origin xyz="-0.10 0.07 0.045" rpy="-1.57 0.0 0.0"/> -->
            <origin xyz="0.0 0.0 0.0" rpy="0.0 0.0 0.0"/>
            <geometry>
                <cylinder radius="0.045" length="0.01"/>
            </geometry>
            <material name="">
                <color rgba="0.0 0.0 0.0 1.0"/>
                <texture filename=""/>
            </material>
        </visual>
        <collision>
            <origin xyz="0.0 0.0 0.0" rpy="0.0 0.0 0.0"/>
            <geometry>
                 <cylinder radius="0.045" length="0.01"/>
            </geometry>
        </collision>
    </link>

    <!-- back right wheel -->
    <joint name="back_right_wheel" type="continuous">
        <origin xyz="-0.10 -0.07 0.045" rpy="-1.57 0.0 0.0"/>
        <parent link="base_link"/>
        <child link="back_right_wheel_link"/>
        <axis xyz="0.0 0.0 1.0"/>
        <limit lower="0.0" upper="0.0" effort="0.0" velocity="0.0"/>
    </joint>

    <link name="back_right_wheel_link">
        <inertial>
            <origin xyz="0.0 0.0 0.0" rpy="0.0 0.0 0.0"/>
            <mass value="0.0"/>
            <inertia ixx="0.0" ixy="0.0" ixz="0.0" iyy="0.0" iyz="0.0" izz="0.0"/>
        </inertial>
        <visual name="">
            <origin xyz="0.0 0.0 0.0" rpy="0.0 0.0 0.0"/>
            <geometry>
                <cylinder radius="0.045" length="0.01"/>
            </geometry>
            <material name="">
                <color rgba="0.0 0.0 0.0 1.0"/>
                <texture filename=""/>
            </material>
        </visual>
        <collision>
            <origin xyz="0.0 0.0 0.0" rpy="0.0 0.0 0.0"/>
            <geometry>
                 <cylinder radius="0.045" length="0.01"/>
            </geometry>
        </collision>
    </link>
</robot>